[0m11:48:06.186628 [debug] [MainThread]: Sending event: {'category': 'dbt', 'action': 'invocation', 'label': 'start', 'context': [<snowplow_tracker.self_describing_json.SelfDescribingJson object at 0x000001E5B85A7650>, <snowplow_tracker.self_describing_json.SelfDescribingJson object at 0x000001E5B855A1D0>, <snowplow_tracker.self_describing_json.SelfDescribingJson object at 0x000001E5B85A5810>]}


============================== 11:48:06.191633 | f0f82ee5-3f08-469c-8af4-4efae488a7f2 ==============================
[0m11:48:06.191633 [info ] [MainThread]: Running with dbt=1.8.0
[0m11:48:06.192629 [debug] [MainThread]: running dbt with arguments {'printer_width': '80', 'indirect_selection': 'eager', 'log_cache_events': 'False', 'write_json': 'True', 'partial_parse': 'True', 'cache_selected_only': 'False', 'profiles_dir': 'C:\\Users\\compu\\.dbt', 'debug': 'False', 'fail_fast': 'False', 'log_path': 'd:\\REPOS\\DBT_BBVA\\dbt_packages\\dbt_artifacts\\logs', 'version_check': 'True', 'warn_error': 'None', 'use_colors': 'True', 'use_experimental_parser': 'False', 'no_print': 'None', 'quiet': 'False', 'log_format': 'default', 'static_parser': 'True', 'warn_error_options': 'WarnErrorOptions(include=[], exclude=[])', 'invocation_command': 'dbt ', 'target_path': 'None', 'introspect': 'True', 'send_anonymous_usage_stats': 'True'}
[0m11:48:06.409555 [debug] [MainThread]: Sending event: {'category': 'dbt', 'action': 'project_id', 'label': 'f0f82ee5-3f08-469c-8af4-4efae488a7f2', 'context': [<snowplow_tracker.self_describing_json.SelfDescribingJson object at 0x000001E5B85D7190>]}
[0m11:48:06.448554 [debug] [MainThread]: Set downloads directory='C:\Users\compu\AppData\Local\Temp\dbt-downloads-iknjxoc3'
[0m11:48:06.449556 [debug] [MainThread]: Making package index registry request: GET https://hub.getdbt.com/api/v1/index.json
[0m11:48:06.866554 [debug] [MainThread]: Response from registry index: GET https://hub.getdbt.com/api/v1/index.json 200
[0m11:48:06.868554 [debug] [MainThread]: Making package registry request: GET https://hub.getdbt.com/api/v1/dbt-labs/dbt_utils.json
[0m11:48:07.004277 [debug] [MainThread]: Response from registry: GET https://hub.getdbt.com/api/v1/dbt-labs/dbt_utils.json 200
[0m11:48:07.027274 [info ] [MainThread]: Updating lock file in file path: D:\REPOS\DBT_BBVA\dbt_packages\dbt_artifacts/package-lock.yml
[0m11:48:07.044274 [debug] [MainThread]: Set downloads directory='C:\Users\compu\AppData\Local\Temp\dbt-downloads-_8kej8b9'
[0m11:48:07.051270 [info ] [MainThread]: Installing dbt-labs/dbt_utils
[0m11:48:13.256070 [error] [MainThread]: Encountered an error:
[WinError 32] El proceso no tiene acceso al archivo porque est√° siendo utilizado por otro proceso: 'dbt_packages\\dbt-utils-0.8.6\\integration_tests'
[0m11:48:13.526070 [error] [MainThread]: Traceback (most recent call last):
  File "C:\Program Files\Python311\Lib\shutil.py", line 824, in move
    os.rename(src, real_dst)
PermissionError: [WinError 32] El proceso no tiene acceso al archivo porque est√° siendo utilizado por otro proceso: 'dbt_packages\\dbt-utils-0.8.6' -> 'dbt_packages\\dbt_utils'

During handling of the above exception, another exception occurred:

Traceback (most recent call last):
  File "C:\Users\compu\AppData\Roaming\Python\Python311\site-packages\dbt\cli\requires.py", line 138, in wrapper
    result, success = func(*args, **kwargs)
                      ^^^^^^^^^^^^^^^^^^^^^
  File "C:\Users\compu\AppData\Roaming\Python\Python311\site-packages\dbt\cli\requires.py", line 101, in wrapper
    return func(*args, **kwargs)
           ^^^^^^^^^^^^^^^^^^^^^
  File "C:\Users\compu\AppData\Roaming\Python\Python311\site-packages\dbt\cli\requires.py", line 201, in wrapper
    return func(*args, **kwargs)
           ^^^^^^^^^^^^^^^^^^^^^
  File "C:\Users\compu\AppData\Roaming\Python\Python311\site-packages\dbt\cli\requires.py", line 247, in wrapper
    return func(*args, **kwargs)
           ^^^^^^^^^^^^^^^^^^^^^
  File "C:\Users\compu\AppData\Roaming\Python\Python311\site-packages\dbt\cli\main.py", line 446, in deps
    results = task.run()
              ^^^^^^^^^^
  File "C:\Users\compu\AppData\Roaming\Python\Python311\site-packages\dbt\task\deps.py", line 260, in run
    package.install(self.project, renderer)
  File "C:\Users\compu\AppData\Roaming\Python\Python311\site-packages\dbt\deps\registry.py", line 66, in install
    self._install(project, renderer)
  File "C:\Users\compu\AppData\Roaming\Python\Python311\site-packages\dbt\deps\base.py", line 121, in _install
    connection_exception_retry(download_untar_fn, 5)
  File "C:\Users\compu\AppData\Roaming\Python\Python311\site-packages\dbt_common\utils\connection.py", line 21, in connection_exception_retry
    return fn()
           ^^^^
  File "C:\Users\compu\AppData\Roaming\Python\Python311\site-packages\dbt\deps\base.py", line 133, in download_and_untar
    system.untar_package(tar_path, deps_path, package_name)
  File "C:\Users\compu\AppData\Roaming\Python\Python311\site-packages\dbt_common\clients\system.py", line 646, in untar_package
    dbt_common.clients.system.rename(downloaded_path, desired_path, force=True)
  File "C:\Users\compu\AppData\Roaming\Python\Python311\site-packages\dbt_common\clients\system.py", line 609, in rename
    shutil.move(from_path, to_path)
  File "C:\Program Files\Python311\Lib\shutil.py", line 842, in move
    rmtree(src)
  File "C:\Program Files\Python311\Lib\shutil.py", line 758, in rmtree
    return _rmtree_unsafe(path, onerror)
           ^^^^^^^^^^^^^^^^^^^^^^^^^^^^^
  File "C:\Program Files\Python311\Lib\shutil.py", line 616, in _rmtree_unsafe
    _rmtree_unsafe(fullname, onerror)
  File "C:\Program Files\Python311\Lib\shutil.py", line 625, in _rmtree_unsafe
    onerror(os.rmdir, path, sys.exc_info())
  File "C:\Program Files\Python311\Lib\shutil.py", line 623, in _rmtree_unsafe
    os.rmdir(path)
PermissionError: [WinError 32] El proceso no tiene acceso al archivo porque est√° siendo utilizado por otro proceso: 'dbt_packages\\dbt-utils-0.8.6\\integration_tests'

[0m11:48:13.531071 [debug] [MainThread]: Command `cli deps` failed at 11:48:13.530071 after 7.46 seconds
[0m11:48:13.532070 [debug] [MainThread]: Sending event: {'category': 'dbt', 'action': 'invocation', 'label': 'end', 'context': [<snowplow_tracker.self_describing_json.SelfDescribingJson object at 0x000001E5B80B3AD0>, <snowplow_tracker.self_describing_json.SelfDescribingJson object at 0x000001E5B814AE10>, <snowplow_tracker.self_describing_json.SelfDescribingJson object at 0x000001E5B8558C50>]}
[0m11:48:13.533070 [debug] [MainThread]: Flushing usage events
